Workbook

Sheet Rent Chart
A1: The Boardwalk vs. HelloData Comp Set
A2: July 2025 – June 2026
A3: Rent chart only considers new leases
A5: Month | B5: The Boardwalk Lease Count | C5: The Boardwalk Gross PSF | D5: The Boardwalk Effective PSF | E5: Comp Set Lease Count | F5: Comp Set Gross PSF | G5: Comp Set Effective PSF
A6: Jul-25 | B6: =COUNTIF('The Boardwalk (Yardi)'!P2:P183,"2025-07") -> 12 | C6: =IFERROR(SUMIFS('The Boardwalk (Yardi)'!I2:I183,'The Boardwalk (Yardi)'!P2:P183,"2025-07")/SUMIFS('The Boardwalk (Yardi)'!E2:E183,'The Boardwalk (Yardi)'!P2:P183,"2025-07"),"") -> 1.8315277 | D6: =IFERROR(SUMIFS('The Boardwalk (Yardi)'!M2:M183,'The Boardwalk (Yardi)'!P2:P183,"2025-07")/SUMIFS('The Boardwalk (Yardi)'!E2:E183,'The Boardwalk (Yardi)'!P2:P183,"2025-07"),"") -> 1.6261009 | E6: =COUNTIF('Comp Set (HelloData)'!N2:N1006,"2025-07") -> 42 | F6: =IFERROR(SUMIFS('Comp Set (HelloData)'!J2:J1006,'Comp Set (HelloData)'!N2:N1006,"2025-07")/SUMIFS('Comp Set (HelloData)'!F2:F1006,'Comp Set (HelloData)'!N2:N1006,"2025-07"),"") -> 1.7098044 | G6: =IFERROR(SUMIFS('Comp Set (HelloData)'!L2:L1006,'Comp Set (HelloData)'!N2:N1006,"2025-07")/SUMIFS('Comp Set (HelloData)'!F2:F1006,'Comp Set (HelloData)'!N2:N1006,"2025-07"),"") -> 1.5016327
A7: Aug-25 | B7: =COUNTIF('The Boardwalk (Yardi)'!P2:P183,"2025-08") -> 18 | C7: =IFERROR(SUMIFS('The Boardwalk (Yardi)'!I2:I183,'The Boardwalk (Yardi)'!P2:P183,"2025-08")/SUMIFS('The Boardwalk (Yardi)'!E2:E183,'The Boardwalk (Yardi)'!P2:P183,"2025-08"),"") -> 1.7543273 | D7: =IFERROR(SUMIFS('The Boardwalk (Yardi)'!M2:M183,'The Boardwalk (Yardi)'!P2:P183,"2025-08")/SUMIFS('The Boardwalk (Yardi)'!E2:E183,'The Boardwalk (Yardi)'!P2:P183,"2025-08"),"") -> 1.5840303 | E7: =COUNTIF('Comp Set (HelloData)'!N2:N1006,"2025-08") -> 61 | F7: =IFERROR(SUMIFS('Comp Set (HelloData)'!J2:J1006,'Comp Set (HelloData)'!N2:N1006,"2025-08")/SUMIFS('Comp Set (HelloData)'!F2:F1006,'Comp Set (HelloData)'!N2:N1006,"2025-08"),"") -> 1.6184528 | G7: =IFERROR(SUMIFS('Comp Set (HelloData)'!L2:L1006,'Comp Set (HelloData)'!N2:N1006,"2025-08")/SUMIFS('Comp Set (HelloData)'!F2:F1006,'Comp Set (HelloData)'!N2:N1006,"2025-08"),"") -> 1.4527451
A8: Sep-25 | B8: =COUNTIF('The Boardwalk (Yardi)'!P2:P183,"2025-09") -> 15 | C8: =IFERROR(SUMIFS('The Boardwalk (Yardi)'!I2:I183,'The Boardwalk (Yardi)'!P2:P183,"2025-09")/SUMIFS('The Boardwalk (Yardi)'!E2:E183,'The Boardwalk (Yardi)'!P2:P183,"2025-09"),"") -> 1.5410359 | D8: =IFERROR(SUMIFS('The Boardwalk (Yardi)'!M2:M183,'The Boardwalk (Yardi)'!P2:P183,"2025-09")/SUMIFS('The Boardwalk (Yardi)'!E2:E183,'The Boardwalk (Yardi)'!P2:P183,"2025-09"),"") -> 1.4249793 | E8: =COUNTIF('Comp Set (HelloData)'!N2:N1006,"2025-09") -> 72 | F8: =IFERROR(SUMIFS('Comp Set (HelloData)'!J2:J1006,'Comp Set (HelloData)'!N2:N1006,"2025-09")/SUMIFS('Comp Set (HelloData)'!F2:F1006,'Comp Set (HelloData)'!N2:N1006,"2025-09"),"") -> 1.5600728 | G8: =IFERROR(SUMIFS('Comp Set (HelloData)'!L2:L1006,'Comp Set (HelloData)'!N2:N1006,"2025-09")/SUMIFS('Comp Set (HelloData)'!F2:F1006,'Comp Set (HelloData)'!N2:N1006,"2025-09"),"") -> 1.3643849
A9: Oct-25 | B9: =COUNTIF('The Boardwalk (Yardi)'!P2:P183,"2025-10") -> 11 | C9: =IFERROR(SUMIFS('The Boardwalk (Yardi)'!I2:I183,'The Boardwalk (Yardi)'!P2:P183,"2025-10")/SUMIFS('The Boardwalk (Yardi)'!E2:E183,'The Boardwalk (Yardi)'!P2:P183,"2025-10"),"") -> 1.4895905 | D9: =IFERROR(SUMIFS('The Boardwalk (Yardi)'!M2:M183,'The Boardwalk (Yardi)'!P2:P183,"2025-10")/SUMIFS('The Boardwalk (Yardi)'!E2:E183,'The Boardwalk (Yardi)'!P2:P183,"2025-10"),"") -> 1.359381 | E9: =COUNTIF('Comp Set (HelloData)'!N2:N1006,"2025-10") -> 99 | F9: =IFERROR(SUMIFS('Comp Set (HelloData)'!J2:J1006,'Comp Set (HelloData)'!N2:N1006,"2025-10")/SUMIFS('Comp Set (HelloData)'!F2:F1006,'Comp Set (HelloData)'!N2:N1006,"2025-10"),"") -> 1.5356058 | G9: =IFERROR(SUMIFS('Comp Set (HelloData)'!L2:L1006,'Comp Set (HelloData)'!N2:N1006,"2025-10")/SUMIFS('Comp Set (HelloData)'!F2:F1006,'Comp Set (HelloData)'!N2:N1006,"2025-10"),"") -> 1.3191134
A10: Nov-25 | B10: =COUNTIF('The Boardwalk (Yardi)'!P2:P183,"2025-11") -> 8 | C10: =IFERROR(SUMIFS('The Boardwalk (Yardi)'!I2:I183,'The Boardwalk (Yardi)'!P2:P183,"2025-11")/SUMIFS('The Boardwalk (Yardi)'!E2:E183,'The Boardwalk (Yardi)'!P2:P183,"2025-11"),"") -> 1.4648225 | D10: =IFERROR(SUMIFS('The Boardwalk (Yardi)'!M2:M183,'The Boardwalk (Yardi)'!P2:P183,"2025-11")/SUMIFS('The Boardwalk (Yardi)'!E2:E183,'The Boardwalk (Yardi)'!P2:P183,"2025-11"),"") -> 1.3216161 | E10: =COUNTIF('Comp Set (HelloData)'!N2:N1006,"2025-11") -> 82 | F10: =IFERROR(SUMIFS('Comp Set (HelloData)'!J2:J1006,'Comp Set (HelloData)'!N2:N1006,"2025-11")/SUMIFS('Comp Set (HelloData)'!F2:F1006,'Comp Set (HelloData)'!N2:N1006,"2025-11"),"") -> 1.4717653 | G10: =IFERROR(SUMIFS('Comp Set (HelloData)'!L2:L1006,'Comp Set (HelloData)'!N2:N1006,"2025-11")/SUMIFS('Comp Set (HelloData)'!F2:F1006,'Comp Set (HelloData)'!N2:N1006,"2025-11"),"") -> 1.2588603
A11: Dec-25 | B11: =COUNTIF('The Boardwalk (Yardi)'!P2:P183,"2025-12") -> 11 | C11: =IFERROR(SUMIFS('The Boardwalk (Yardi)'!I2:I183,'The Boardwalk (Yardi)'!P2:P183,"2025-12")/SUMIFS('The Boardwalk (Yardi)'!E2:E183,'The Boardwalk (Yardi)'!P2:P183,"2025-12"),"") -> 1.3009031 | D11: =IFERROR(SUMIFS('The Boardwalk (Yardi)'!M2:M183,'The Boardwalk (Yardi)'!P2:P183,"2025-12")/SUMIFS('The Boardwalk (Yardi)'!E2:E183,'The Boardwalk (Yardi)'!P2:P183,"2025-12"),"") -> 1.1379637 | E11: =COUNTIF('Comp Set (HelloData)'!N2:N1006,"2025-12") -> 88 | F11: =IFERROR(SUMIFS('Comp Set (HelloData)'!J2:J1006,'Comp Set (HelloData)'!N2:N1006,"2025-12")/SUMIFS('Comp Set (HelloData)'!F2:F1006,'Comp Set (HelloData)'!N2:N1006,"2025-12"),"") -> 1.372692 | G11: =IFERROR(SUMIFS('Comp Set (HelloData)'!L2:L1006,'Comp Set (HelloData)'!N2:N1006,"2025-12")/SUMIFS('Comp Set (HelloData)'!F2:F1006,'Comp Set (HelloData)'!N2:N1006,"2025-12"),"") -> 1.2301164
A12: Jan-26 | B12: =COUNTIF('The Boardwalk (Yardi)'!P2:P183,"2026-01") -> 22 | C12: =IFERROR(SUMIFS('The Boardwalk (Yardi)'!I2:I183,'The Boardwalk (Yardi)'!P2:P183,"2026-01")/SUMIFS('The Boardwalk (Yardi)'!E2:E183,'The Boardwalk (Yardi)'!P2:P183,"2026-01"),"") -> 1.3448294 | D12: =IFERROR(SUMIFS('The Boardwalk (Yardi)'!M2:M183,'The Boardwalk (Yardi)'!P2:P183,"2026-01")/SUMIFS('The Boardwalk (Yardi)'!E2:E183,'The Boardwalk (Yardi)'!P2:P183,"2026-01"),"") -> 1.1519357 | E12: =COUNTIF('Comp Set (HelloData)'!N2:N1006,"2026-01") -> 91 | F12: =IFERROR(SUMIFS('Comp Set (HelloData)'!J2:J1006,'Comp Set (HelloData)'!N2:N1006,"2026-01")/SUMIFS('Comp Set (HelloData)'!F2:F1006,'Comp Set (HelloData)'!N2:N1006,"2026-01"),"") -> 1.4999368 | G12: =IFERROR(SUMIFS('Comp Set (HelloData)'!L2:L1006,'Comp Set (HelloData)'!N2:N1006,"2026-01")/SUMIFS('Comp Set (HelloData)'!F2:F1006,'Comp Set (HelloData)'!N2:N1006,"2026-01"),"") -> 1.2858478
A13: Feb-26 | B13: =COUNTIF('The Boardwalk (Yardi)'!P2:P183,"2026-02") -> 20 | C13: =IFERROR(SUMIFS('The Boardwalk (Yardi)'!I2:I183,'The Boardwalk (Yardi)'!P2:P183,"2026-02")/SUMIFS('The Boardwalk (Yardi)'!E2:E183,'The Boardwalk (Yardi)'!P2:P183,"2026-02"),"") -> 1.2663504 | D13: =IFERROR(SUMIFS('The Boardwalk (Yardi)'!M2:M183,'The Boardwalk (Yardi)'!P2:P183,"2026-02")/SUMIFS('The Boardwalk (Yardi)'!E2:E183,'The Boardwalk (Yardi)'!P2:P183,"2026-02"),"") -> 1.1830208 | E13: =COUNTIF('Comp Set (HelloData)'!N2:N1006,"2026-02") -> 109 | F13: =IFERROR(SUMIFS('Comp Set (HelloData)'!J2:J1006,'Comp Set (HelloData)'!N2:N1006,"2026-02")/SUMIFS('Comp Set (HelloData)'!F2:F1006,'Comp Set (HelloData)'!N2:N1006,"2026-02"),"") -> 1.5332765 | G13: =IFERROR(SUMIFS('Comp Set (HelloData)'!L2:L1006,'Comp Set (HelloData)'!N2:N1006,"2026-02")/SUMIFS('Comp Set (HelloData)'!F2:F1006,'Comp Set (HelloData)'!N2:N1006,"2026-02"),"") -> 1.3156624
A14: Mar-26 | B14: =COUNTIF('The Boardwalk (Yardi)'!P2:P183,"2026-03") -> 29 | C14: =IFERROR(SUMIFS('The Boardwalk (Yardi)'!I2:I183,'The Boardwalk (Yardi)'!P2:P183,"2026-03")/SUMIFS('The Boardwalk (Yardi)'!E2:E183,'The Boardwalk (Yardi)'!P2:P183,"2026-03"),"") -> 1.2623535 | D14: =IFERROR(SUMIFS('The Boardwalk (Yardi)'!M2:M183,'The Boardwalk (Yardi)'!P2:P183,"2026-03")/SUMIFS('The Boardwalk (Yardi)'!E2:E183,'The Boardwalk (Yardi)'!P2:P183,"2026-03"),"") -> 1.2594171 | E14: =COUNTIF('Comp Set (HelloData)'!N2:N1006,"2026-03") -> 82 | F14: =IFERROR(SUMIFS('Comp Set (HelloData)'!J2:J1006,'Comp Set (HelloData)'!N2:N1006,"2026-03")/SUMIFS('Comp Set (HelloData)'!F2:F1006,'Comp Set (HelloData)'!N2:N1006,"2026-03"),"") -> 1.5671926 | G14: =IFERROR(SUMIFS('Comp Set (HelloData)'!L2:L1006,'Comp Set (HelloData)'!N2:N1006,"2026-03")/SUMIFS('Comp Set (HelloData)'!F2:F1006,'Comp Set (HelloData)'!N2:N1006,"2026-03"),"") -> 1.3580272
A15: Apr-26 | B15: =COUNTIF('The Boardwalk (Yardi)'!P2:P183,"2026-04") -> 16 | C15: =IFERROR(SUMIFS('The Boardwalk (Yardi)'!I2:I183,'The Boardwalk (Yardi)'!P2:P183,"2026-04")/SUMIFS('The Boardwalk (Yardi)'!E2:E183,'The Boardwalk (Yardi)'!P2:P183,"2026-04"),"") -> 1.28679 | D15: =IFERROR(SUMIFS('The Boardwalk (Yardi)'!M2:M183,'The Boardwalk (Yardi)'!P2:P183,"2026-04")/SUMIFS('The Boardwalk (Yardi)'!E2:E183,'The Boardwalk (Yardi)'!P2:P183,"2026-04"),"") -> 1.28679 | E15: =COUNTIF('Comp Set (HelloData)'!N2:N1006,"2026-04") -> 81 | F15: =IFERROR(SUMIFS('Comp Set (HelloData)'!J2:J1006,'Comp Set (HelloData)'!N2:N1006,"2026-04")/SUMIFS('Comp Set (HelloData)'!F2:F1006,'Comp Set (HelloData)'!N2:N1006,"2026-04"),"") -> 1.6419771 | G15: =IFERROR(SUMIFS('Comp Set (HelloData)'!L2:L1006,'Comp Set (HelloData)'!N2:N1006,"2026-04")/SUMIFS('Comp Set (HelloData)'!F2:F1006,'Comp Set (HelloData)'!N2:N1006,"2026-04"),"") -> 1.3877575
A16: May-26 | B16: =COUNTIF('The Boardwalk (Yardi)'!P2:P183,"2026-05") -> 7 | C16: =IFERROR(SUMIFS('The Boardwalk (Yardi)'!I2:I183,'The Boardwalk (Yardi)'!P2:P183,"2026-05")/SUMIFS('The Boardwalk (Yardi)'!E2:E183,'The Boardwalk (Yardi)'!P2:P183,"2026-05"),"") -> 1.5155494 | D16: =IFERROR(SUMIFS('The Boardwalk (Yardi)'!M2:M183,'The Boardwalk (Yardi)'!P2:P183,"2026-05")/SUMIFS('The Boardwalk (Yardi)'!E2:E183,'The Boardwalk (Yardi)'!P2:P183,"2026-05"),"") -> 1.5155494 | E16: =COUNTIF('Comp Set (HelloData)'!N2:N1006,"2026-05") -> 111 | F16: =IFERROR(SUMIFS('Comp Set (HelloData)'!J2:J1006,'Comp Set (HelloData)'!N2:N1006,"2026-05")/SUMIFS('Comp Set (HelloData)'!F2:F1006,'Comp Set (HelloData)'!N2:N1006,"2026-05"),"") -> 1.5747967 | G16: =IFERROR(SUMIFS('Comp Set (HelloData)'!L2:L1006,'Comp Set (HelloData)'!N2:N1006,"2026-05")/SUMIFS('Comp Set (HelloData)'!F2:F1006,'Comp Set (HelloData)'!N2:N1006,"2026-05"),"") -> 1.2646742
A17: Jun-26 | B17: =COUNTIF('The Boardwalk (Yardi)'!P2:P183,"2026-06") -> 13 | C17: =IFERROR(SUMIFS('The Boardwalk (Yardi)'!I2:I183,'The Boardwalk (Yardi)'!P2:P183,"2026-06")/SUMIFS('The Boardwalk (Yardi)'!E2:E183,'The Boardwalk (Yardi)'!P2:P183,"2026-06"),"") -> 1.5444292 | D17: =IFERROR(SUMIFS('The Boardwalk (Yardi)'!M2:M183,'The Boardwalk (Yardi)'!P2:P183,"2026-06")/SUMIFS('The Boardwalk (Yardi)'!E2:E183,'The Boardwalk (Yardi)'!P2:P183,"2026-06"),"") -> 1.5323581 | E17: =COUNTIF('Comp Set (HelloData)'!N2:N1006,"2026-06") -> 87 | F17: =IFERROR(SUMIFS('Comp Set (HelloData)'!J2:J1006,'Comp Set (HelloData)'!N2:N1006,"2026-06")/SUMIFS('Comp Set (HelloData)'!F2:F1006,'Comp Set (HelloData)'!N2:N1006,"2026-06"),"") -> 1.5154768 | G17: =IFERROR(SUMIFS('Comp Set (HelloData)'!L2:L1006,'Comp Set (HelloData)'!N2:N1006,"2026-06")/SUMIFS('Comp Set (HelloData)'!F2:F1006,'Comp Set (HelloData)'!N2:N1006,"2026-06"),"") -> 1.2939175
A18: T12 Total / SF-Wtd | B18: =SUM(B6:B17) -> 182 | C18: =IFERROR(SUM('The Boardwalk (Yardi)'!I2:I183)/SUM('The Boardwalk (Yardi)'!E2:E183),0) -> 1.4333113 | D18: =IFERROR(SUM('The Boardwalk (Yardi)'!M2:M183)/SUM('The Boardwalk (Yardi)'!E2:E183),0) -> 1.3370167 | E18: =SUM(E6:E17) -> 1005 | F18: =IFERROR(SUM('Comp Set (HelloData)'!J2:J1006)/SUM('Comp Set (HelloData)'!F2:F1006),0) -> 1.5388429 | G18: =IFERROR(SUM('Comp Set (HelloData)'!L2:L1006)/SUM('Comp Set (HelloData)'!F2:F1006),0) -> 1.3217804
A48: Methodology
A49: Property lines (Yardi)
A50: Source: Yardi LTO report (RRG-10658) — 12-month+ term new leases (Move Ins), Jul 2025 – Jun 2026 lease start. Unit Transfers and Lease Renewals excluded.
A51: • 182 new-lease Move Ins over the T12 window (12-month+ terms).
A52: Gross PSF = Lease Rent / Sqft. Effective PSF = Effective Rent / Sqft (net of upfront concessions and free months).
A53: SF-weighted at monthly level: sum of dollars leased that month / sum of SF leased that month.
A55: Comp lines (HelloData closed listings)
A56: Source: HelloData Unit-Level Data — Leased Date between 2025-07-01 and 2026-06-30. Same SF-weighted methodology.
A57: Comp set (10 properties, 1,005 closed comp leases over T12):
A58: • The Park at Veneto (174)
A59: • 39 Acres (164)
A60: • Brantley Pines Apartments (130)
... A97: May 2026 (7 subject leases) is the thinnest month — its .52 gross recovery reading should be treated with caution. All other months have 8+ subject leases and are reasonably reliable.

Sheet The Boardwalk (Yardi)
A1: Source | B1: Resident Name | C1: Unit Type | D1: Unit | E1: Sqft | F1: Lease Start | G1: Lease Term | H1: Market Rent | I1: Lease Rent | J1: Up-Front Concessions | K1: Months Free | L1: Total Concessions | M1: Effective Rent | N1: Gross PSF | O1: Effective PSF | P1: Month
A2: Move Ins | B2: Rodrigue Javel | C2: BWK.C2 | D2: 4640H242 | E2: 1130 | F2: 45841 | G2: 12 | H2: 1825 | I2: 1825 | J2: 1825 | K2: 1 | L2: 1825 | M2: 1672.9167 | N2: =IFERROR(I2/E2,0) -> 1.6150442 | O2: =IFERROR(M2/E2,0) -> 1.4804572 | P2: 2025-07
A3: Move Ins | B3: Lisandra Valdes | C3: BWK.B0 | D3: 4665K169 | E3: 814 | F3: 45843 | G3: 12 | H3: 1499 | I3: 1499 | J3: 1499 | K3: 1 | L3: 1499 | M3: 1374.0833 | N3: =IFERROR(I3/E3,0) -> 1.8415233 | O3: =IFERROR(M3/E3,0) -> 1.6880631 | P3: 2025-07
A4: Move Ins | B4: Colton Shore | C4: BWK.S2 | D4: 4775A102 | E4: 500 | F4: 45846 | G4: 12 | H4: 1090 | I4: 1090 | J4: 1090 | K4: 1 | L4: 1090 | M4: 999.16667 | N4: =IFERROR(I4/E4,0) -> 2.18 | O4: =IFERROR(M4/E4,0) -> 1.9983333 | P4: 2025-07
A5: Move Ins | B5: Trinity Mclane | C5: BWK.A1 | D5: 4755B215 | E5: 657 | F5: 45847 | G5: 12 | H5: 1240 | I5: 1240 | J5: 2480 | K5: 2 | L5: 2480 | M5: 1033.3333 | N5: =IFERROR(I5/E5,0) -> 1.8873668 | O5: =IFERROR(M5/E5,0) -> 1.5728057 | P5: 2025-07
A6: Move Ins | B6: Aaron Brown | C6: BWK.B2 | D6: 4622B207 | E6: 930 | F6: 45852 | G6: 12 | H6: 1329 | I6: 1424 | J6: 2848 | K6: 2 | L6: 2848 | M6: 1186.6667 | N6: =IFERROR(I6/E6,0) -> 1.5311828 | O6: =IFERROR(M6/E6,0) -> 1.2759857 | P6: 2025-07
A7: Move Ins | B7: Mikayla Close | C7: BWK.S1 | D7: 4658M174 | E7: 550 | F7: 45853 | G7: 12 | H7: 1195 | I7: 1195 | J7: 1792.5 | K7: 1.5 | L7: 1792.5 | M7: 1045.625 | N7: =IFERROR(I7/E7,0) -> 2.1727273 | O7: =IFERROR(M7/E7,0) -> 1.9011364 | P7: 2025-07
A8: Move Ins | B8: Keesha Samuels | C8: BWK.A1 | D8: 4755B110 | E8: 657 | F8: 45856 | G8: 12 | H8: 1330 | I8: 1330 | J8: 2660 | K8: 2 | L8: 2660 | M8: 1108.3333 | N8: =IFERROR(I8/E8,0) -> 2.0243531 | O8: =IFERROR(M8/E8,0) -> 1.6869609 | P8: 2025-07
A9: Move Ins | B9: Aaron Langley | C9: BWK.S1 | D9: 4662N180 | E9: 550 | F9: 45857 | G9: 12 | H9: 1020 | I9: 1020 | J9: 0 | K9: 0 | L9: 0 | M9: 1020 | N9: =IFERROR(I9/E9,0) -> 1.8545455 | O9: =IFERROR(M9/E9,0) -> 1.8545455 | P9: 2025-07
A10: Move Ins | B10: Antoinette Shanks | C10: BWK.C2 | D10: 4640H236 | E10: 1130 | F10: 45861 | G10: 12 | H10: 1735 | I10: 1735 | J10: 3720 | K10: 2.1440922 | L10: 3720 | M10: 1425 | N10: =IFERROR(I10/E10,0) -> 1.5353982 | O10: =IFERROR(M10/E10,0) -> 1.2610619 | P10: 2025-07
A11: Move Ins | B11: Dayana Etheart | C11: BWK.A1 | D11: 4735C122 | E11: 657 | F11: 45863 | G11: 12 | H11: 1255 | I11: 1255 | J11: 1255 | K11: 1 | L11: 1255 | M11: 1150.4167 | N11: =IFERROR(I11/E11,0) -> 1.9101979 | O11: =IFERROR(M11/E11,0) -> 1.7510147 | P11: 2025-07
A12: Move Ins | B12: Micah Tucker | C12: BWK.A1 | D12: 4775A204 | E12: 657 | F12: 45863 | G12: 12 | H12: 1390 | I12: 1390 | J12: 0 | K12: 0 | L12: 0 | M12: 1390 | N12: =IFERROR(I12/E12,0) -> 2.1156773 | O12: =IFERROR(M12/E12,0) -> 2.1156773 | P12: 2025-07
A13: Move Ins | B13: Vidalia Salinas | C13: BWK.B0 | D13: 4635I156 | E13: 814 | F13: 45866 | G13: 12 | H13: 1565 | I13: 1565 | J13: 3130 | K13: 2 | L13: 3130 | M13: 1304.1667 | N13: =IFERROR(I13/E13,0) -> 1.9226044 | O13: =IFERROR(M13/E13,0) -> 1.6021704 | P13: 2025-07
... A183: Move Ins | B183: Gregory Mcmurrin | C183: BWK.S1 | D183: 4658M171 | E183: 550 | F183: 46203 | G183: 12 | H183: 1096 | I183: 1096 | J183: 0 | K183: 0 | L183: 0 | M183: 1096 | N183: =IFERROR(I183/E183,0) -> 1.9927273 | O183: =IFERROR(M183/E183,0) -> 1.9927273 | P183: 2026-06

Sheet Comp Set (HelloData)
A1: Property Name | B1: Floorplan Name | C1: Unit # | D1: Beds | E1: Baths | F1: Sqft | G1: First Listed | H1: Leased Date | I1: Days on Mkt | J1: Asking Rent | K1: Asking PSF | L1: Effective Rent | M1: Effective PSF | N1: Month
A2: 39 Acres | B2: B3 | C2: 1704 | D2: 2 | E2: 2 | F2: 903 | G2: 45826 | H2: 45839 | I2: 14 | J2: 1765 | K2: =IFERROR(J2/F2,0) -> 1.9545958 | L2: 1471 | M2: =IFERROR(L2/F2,0) -> 1.6290144 | N2: 2025-07
A3: Coral Cove | B3: 2BR-2 | C3: 0522 | D3: 2 | E3: 2 | F3: 1001 | G3: 45784 | H3: 45839 | I3: 56 | J3: 1425 | K3: =IFERROR(J3/F3,0) -> 1.4235764 | L3: 1425 | M3: =IFERROR(L3/F3,0) -> 1.4235764 | N3: 2025-07
A4: The Park at Positano | B4: Venice - Rehab | C4: 25-207 | D4: 1 | E4: 1 | F4: 762 | G4: 45790 | H4: 45840 | I4: 51 | J4: 1278 | K4: =IFERROR(J4/F4,0) -> 1.6771654 | L4: 1081 | M4: =IFERROR(L4/F4,0) -> 1.4186352 | N4: 2025-07
A5: 39 Acres | B5: A3 | C5: 1303 | D5: 1 | E5: 1 | F5: 726 | G5: 45667 | H5: 45841 | I5: 175 | J5: 1489 | K5: =IFERROR(J5/F5,0) -> 2.0509642 | L5: 1241 | M5: =IFERROR(L5/F5,0) -> 1.7093664 | N5: 2025-07
A6: Brantley Pines Apartments | B6: 2BD / 2BR - 958 sqft | C6: 1011 | D6: 2 | E6: 2 | F6: 958 | G6: 45835 | H6: 45841 | I6: 7 | J6: 1750 | K6: =IFERROR(J6/F6,0) -> 1.8267223 | L6: 1604 | M6: =IFERROR(L6/F6,0) -> 1.6743215 | N6: 2025-07
A7: The Park at Veneto | B7: 1 Bed 1 Bath Large - Partial R | C7: 11-104 | D7: 1 | E7: 1 | F7: 757 | G7: 45820 | H7: 45841 | I7: 22 | J7: 1274 | K7: =IFERROR(J7/F7,0) -> 1.682959 | L7: 1078 | M7: =IFERROR(L7/F7,0) -> 1.4240423 | N7: 2025-07
A8: 39 Acres | B8: B1 | C8: 1408 | D8: 2 | E8: 2 | F8: 810 | G8: 45418 | H8: 45843 | I8: 426 | J8: 1559 | K8: =IFERROR(J8/F8,0) -> 1.9246914 | L8: 1299 | M8: =IFERROR(L8/F8,0) -> 1.6037037 | N8: 2025-07
A9: Brantley Pines Apartments | B9: 1BD / 1BR - 732 sqft | C9: 1311 | D9: 1 | E9: 1 | F9: 732 | G9: 45672 | H9: 45843 | I9: 172 | J9: 1425 | K9: =IFERROR(J9/F9,0) -> 1.9467213 | L9: 1306 | M9: =IFERROR(L9/F9,0) -> 1.784153 | N9: 2025-07
A10: The Laurels | B10: The Palms | C10: A210 | D10: 2 | E10: 1 | F10: 800 | G10: 45798 | H10: 45843 | I10: 46 | J10: 1448 | K10: =IFERROR(J10/F10,0) -> 1.81 | L10: 1448 | M10: =IFERROR(L10/F10,0) -> 1.81 | N10: 2025-07
A11: Brantley Pines Apartments | B11: 2BD / 2BR - 1029 sqft | C11: 1612 | D11: 2 | E11: 2 | F11: 1029 | G11: 45835 | H11: 45844 | I11: 10 | J11: 1900 | K11: =IFERROR(J11/F11,0) -> 1.8464529 | L11: 1742 | M11: =IFERROR(L11/F11,0) -> 1.6929057 | N11: 2025-07
A12: Aria Landings | B12: One Bedroom | C12: 4058-202 | D12: 1 | E12: 1 | F12: 771 | G12: 45793 | H12: 45846 | I12: 54 | J12: 1031 | K12: =IFERROR(J12/F12,0) -> 1.3372244 | L12: 1031 | M12: =IFERROR(L12/F12,0) -> 1.3372244 | N12: 2025-07
A13: The Laurels | B13: The Palms | C13: F204 | D13: 2 | E13: 1 | F13: 800 | G13: 45779 | H13: 45846 | I13: 68 | J13: 1448 | K13: =IFERROR(J13/F13,0) -> 1.81 | L13: 1448 | M13: =IFERROR(L13/F13,0) -> 1.81 | N13: 2025-07
... A53: The Park at Positano | B53: Naples - Rehab | C53: 55-103 | D53: 2 | E53: 2 | F53: 1001 | G53: 45779 | H53: 45874 | I53: 96 | J53: 1462 | K53: =IFERROR(J53/F53,0) -> 1.4605395 | L53: 1282 | M53: =IFERROR(L53/F53,0) -> 1.2807193 | N53: 2025-08
A54: Westchase | B54: 1x1 | D54: 1 | E54: 1 | F54: 702 | G54: 45828 | H54: 45876 | I54: 49 | J54: 1077 | K54: =IFERROR(J54/F54,0) -> 1.534188 | L54: 1077 | M54: =IFERROR(L54/F54,0) -> 1.534188 | N54: 2025-08
A55: Westwood Apartments | B55: Two Bedroom Two Bathroom 60% | C55: 07-7302 | D55: 2 | E55: 2 | F55: 1016 | G55: 45872 | H55: 45876 | I55: 5 | J55: 553 | K55: =IFERROR(J55/F55,0) -> 0.54429134 | L55: 553 | M55: =IFERROR(L55/F55,0) -> 0.54429134 | N55: 2025-08
A56: 39 Acres | B56: A3 | C56: 2315 | D56: 1 | E56: 1 | F56: 726 | G56: 45855 | H56: 45877 | I56: 23 | J56: 1489 | K56: =IFERROR(J56/F56,0) -> 2.0509642 | L56: 1241 | M56: =IFERROR(L56/F56,0) -> 1.7093664 | N56: 2025-08
A57: Coral Cove | B57: 2BR-3 | C57: 0235 | D57: 2 | E57: 2 | F57: 1001 | G57: 45784 | H57: 45877 | I57: 94 | J57: 1500 | K57: =IFERROR(J57/F57,0) -> 1.4985015 | L57: 1500 | M57: =IFERROR(L57/F57,0) -> 1.4985015 | N57: 2025-08
A58: Coral Cove | B58: 2BR-3 | C58: 0631 | D58: 2 | E58: 2 | F58: 1001 | G58: 45873 | H58: 45877 | I58: 5 | J58: 1665 | K58: =IFERROR(J58/F58,0) -> 1.6633367 | L58: 1665 | M58: =IFERROR(L58/F58,0) -> 1.6633367 | N58: 2025-08
A59: The Laurels | B59: The Breeze | C59: M110 | D59: 1 | E59: 1 | F59: 625 | G59: 45804 | H59: 45877 | I59: 74 | J59: 1198 | K59: =IFERROR(J59/F59,0) -> 1.9168 | L59: 1027 | M59: =IFERROR(L59/F59,0) -> 1.6432 | N59: 2025-08
A60: Westwood Apartments | B60: Two Bedroom Two Bathroom 60% | C60: 03-3203 | D60: 2 | E60: 2 | F60: 1016 | G60: 45838 | H60: 45877 | I60: 40 | J60: 1044 | K60: =IFERROR(J60/F60,0) -> 1.0275591 | L60: 1044 | M60: =IFERROR(L60/F60,0) -> 1.0275591 | N60: 2025-08
A61: Westwood Apartments | B61: Two Bedroom Two Bathroom 60% | C61: 12-12304 | D61: 2 | E61: 2 | F61: 1016 | G61: 45876 | H61: 45877 | I61: 2 | J61: 1059 | K61: =IFERROR(J61/F61,0) -> 1.0423228 | L61: 1059 | M61: =IFERROR(L61/F61,0) -> 1.0423228 | N61: 2025-08
A62: The Park at Veneto | B62: 1 Bed 1 Bath Large - Rehab | C62: 07-303 | D62: 1 | E62: 1 | F62: 757 | G62: 45852 | H62: 45878 | I62: 27 | J62: 1321 | K62: =IFERROR(J62/F62,0) -> 1.7450462 | L62: 1118 | M62: =IFERROR(L62/F62,0) -> 1.4768824 | N62: 2025-08
A63: Brantley Pines Apartments | B63: 3BD / 2BR - 1166 sqft | C63: 503 | D63: 3 | E63: 2 | F63: 1166 | G63: 45835 | H63: 45880 | I63: 46 | J63: 2100 | K63: =IFERROR(J63/F63,0) -> 1.8010292 | L63: 1750 | M63: =IFERROR(L63/F63,0) -> 1.5008576 | N63: 2025-08
A64: The Park at Veneto | B64: 1 Bed 1 Bath Large - Rehab | C64: 10-102 | D64: 1 | E64: 1 | F64: 757 | G64: 45822 | H64: 45881 | I64: 60 | J64: 1316 | K64: =IFERROR(J64/F64,0) -> 1.7384412 | L64: 1113 | M64: =IFERROR(L64/F64,0) -> 1.4702774 | N64: 2025-08
A65: 39 Acres | B65: A1 | C65: 0609 | D65: 1 | E65: 1 | F65: 600 | G65: 45727 | H65: 45882 | I65: 156 | J65: 1325 | K65: =IFERROR(J65/F65,0) -> 2.2083333 | L65: 1104 | M65: =IFERROR(L65/F65,0) -> 1.84 | N65: 2025-08
A66: 39 Acres | B66: B2 | C66: 1807 | D66: 2 | E66: 2 | F66: 885 | G66: 45820 | H66: 45882 | I66: 63 | J66: 1669 | K66: =IFERROR(J66/F66,0) -> 1.8858757 | L66: 1391 | M66: =IFERROR(L66/F66,0) -> 1.5717514 | N66: 2025-08
... A90: The Laurels | B90: The Palms | C90: K213 | D90: 2 | E90: 1 | F90: 800 | G90: 45842 | H90: 45892 | I90: 51 | J90: 1593 | K90: =IFERROR(J90/F90,0) -> 1.99125 | L90: 1365 | M90: =IFERROR(L90/F90,0) -> 1.70625 | N90: 2025-08
A91: Aria Landings | B91: Three Bedroom | D91: 3 | E91: 2 | F91: 1244 | G91: 45720 | H91: 45893 | I91: 174 | J91: 1396 | K91: =IFERROR(J91/F91,0) -> 1.1221865 | L91: 1396 | M91: =IFERROR(L91/F91,0) -> 1.1221865 | N91: 2025-08
A92: The Park at Murano | B92: One Bed One Bath - Rehab | C92: 4725-10 | D92: 1 | E92: 1 | F92: 650 | G92: 45861 | H92: 45894 | I92: 34 | J92: 1195 | K92: =IFERROR(J92/F92,0) -> 1.8384615 | L92: 1011 | M92: =IFERROR(L92/F92,0) -> 1.5553846 | N92: 2025-08
A93: The Park at Positano | B93: Naples - Partial Rehab | C93: 51-205 | D93: 2 | E93: 2 | F93: 1001 | G93: 45861 | H93: 45894 | I93: 34 | J93: 1397 | K93: =IFERROR(J93/F93,0) -> 1.3956044 | L93: 1225 | M93: =IFERROR(L93/F93,0) -> 1.2237762 | N93: 2025-08
A94: 39 Acres | B94: B2 | C94: 0708 | D94: 2 | E94: 2 | F94: 885 | G94: 45820 | H94: 45895 | I94: 76 | J94: 1669 | K94: =IFERROR(J94/F94,0) -> 1.8858757 | L94: 1391 | M94: =IFERROR(L94/F94,0) -> 1.5717514 | N94: 2025-08
A95: The Park at Murano | B95: Two Bed Two Bath TH - Rehab | C95: 1585-06 | D95: 2 | E95: 1 | F95: 860 | G95: 45779 | H95: 45895 | I95: 117 | J95: 1437 | K95: =IFERROR(J95/F95,0) -> 1.6709302 | L95: 1216 | M95: =IFERROR(L95/F95,0) -> 1.4139535 | N95: 2025-08
A96: The Park at Veneto | B96: 3 Bed 2 Bath - Partial Rehab | C96: 03-204 | D96: 3 | E96: 2 | F96: 1181 | G96: 45813 | H96: 45895 | I96: 83 | J96: 1669 | K96: =IFERROR(J96/F96,0) -> 1.4132091 | L96: 1412 | M96: =IFERROR(L96/F96,0) -> 1.195597 | N96: 2025-08
A97: Aria Landings | B97: Three Bedroom | C97: 4014-201 | D97: 3 | E97: 2 | F97: 1244 | G97: 45719 | H97: 45896 | I97: 178 | J97: 1396 | K97: =IFERROR(J97/F97,0) -> 1.1221865 | L97: 1396 | M97: =IFERROR(L97/F97,0) -> 1.1221865 | N97: 2025-08
A98: The Park at Murano | B98: One Bed One Bath - Rehab | C98: 1577-31 | D98: 1 | E98: 1 | F98: 650 | G98: 45860 | H98: 45896 | I98: 37 | J98: 1195 | K98: =IFERROR(J98/F98,0) -> 1.8384615 | L98: 1011 | M98: =IFERROR(L98/F98,0) -> 1.5553846 | N98: 2025-08
A99: The Park at Veneto | B99: 2 Bed 1 Bath Small - Partial R | C99: 04-302 | D99: 2 | E99: 2 | F99: 1081 | G99: 45864 | H99: 45896 | I99: 33 | J99: 1389 | K99: =IFERROR(J99/F99,0) -> 1.2849214 | L99: 1175 | M99: =IFERROR(L99/F99,0) -> 1.0869565 | N99: 2025-08
A100: 39 Acres | B100: B1 | C100: 2215 | D100: 2 | E100: 2 | F100: 810 | G100: 45876 | H100: 45898 | I100: 23 | J100: 1559 | K100: =IFERROR(J100/F100,0) -> 1.9246914 | L100: 1299 | M100: =IFERROR(L100/F100,0) -> 1.6037037 | N100: 2025-08
A101: The Park at Veneto | B101: 2 Bed 2 Bath Small - Rehab | C101: 07-311 | D101: 2 | E101: 2 | F101: 1011 | G101: 45892 | H101: 45898 | I101: 7 | J101: 1394 | K101: =IFERROR(J101/F101,0) -> 1.3788328 | L101: 1179 | M101: =IFERROR(L101/F101,0) -> 1.1661721 | N101: 2025-08
A102: The Park at Veneto | B102: 2 Bed 1 Bath Small - Rehab | C102: 04-102 | D102: 2 | E102: 2 | F102: 1081 | G102: 45880 | H102: 45898 | I102: 19 | J102: 1444 | K102: =IFERROR(J102/F102,0) -> 1.3358002 | L102: 1222 | M102: =IFERROR(L102/F102,0) -> 1.1304348 | N102: 2025-08
...
